call this func
 * Serving Flask app "live" (lazy loading)
 * Environment: production
   WARNING: Do not use the development server in a production environment.
   Use a production WSGI server instead.
 * Debug mode: on
 * Running on http://0.0.0.0:8050/ (Press CTRL+C to quit)
 * Restarting with stat
 * Debugger is active!
 * Debugger PIN: 187-529-304
173.230.66.78 - - [09/Jul/2018 03:19:58] "POST /_dash-update-component HTTP/1.1" 500 -
Traceback (most recent call last):
  File "/home/ubuntu/.local/lib/python2.7/site-packages/flask/app.py", line 2309, in __call__
    return self.wsgi_app(environ, start_response)
  File "/home/ubuntu/.local/lib/python2.7/site-packages/flask/app.py", line 2295, in wsgi_app
    response = self.handle_exception(e)
  File "/home/ubuntu/.local/lib/python2.7/site-packages/flask/app.py", line 1741, in handle_exception
    reraise(exc_type, exc_value, tb)
  File "/home/ubuntu/.local/lib/python2.7/site-packages/flask/app.py", line 2292, in wsgi_app
    response = self.full_dispatch_request()
  File "/home/ubuntu/.local/lib/python2.7/site-packages/flask/app.py", line 1815, in full_dispatch_request
    rv = self.handle_user_exception(e)
  File "/home/ubuntu/.local/lib/python2.7/site-packages/flask/app.py", line 1718, in handle_user_exception
    reraise(exc_type, exc_value, tb)
  File "/home/ubuntu/.local/lib/python2.7/site-packages/flask/app.py", line 1813, in full_dispatch_request
    rv = self.dispatch_request()
  File "/home/ubuntu/.local/lib/python2.7/site-packages/flask/app.py", line 1799, in dispatch_request
    return self.view_functions[rule.endpoint](**req.view_args)
  File "/home/ubuntu/.local/lib/python2.7/site-packages/dash/dash.py", line 558, in dispatch
    return self.callback_map[target_id]['callback'](*args)
  File "/home/ubuntu/.local/lib/python2.7/site-packages/dash/dash.py", line 515, in add_context
    output_value = func(*args, **kwargs)
  File "/home/ubuntu/twitch-emotes/src/dash/live.py", line 104, in update_graph_scatter
    max_y = max([max(Y),max(Z)])
ValueError: max() arg is an empty sequence
173.230.66.78 - - [09/Jul/2018 03:20:00] "POST /_dash-update-component HTTP/1.1" 200 -
173.230.66.78 - - [09/Jul/2018 03:20:03] "POST /_dash-update-component HTTP/1.1" 500 -
Traceback (most recent call last):
  File "/home/ubuntu/.local/lib/python2.7/site-packages/flask/app.py", line 2309, in __call__
    return self.wsgi_app(environ, start_response)
  File "/home/ubuntu/.local/lib/python2.7/site-packages/flask/app.py", line 2295, in wsgi_app
    response = self.handle_exception(e)
  File "/home/ubuntu/.local/lib/python2.7/site-packages/flask/app.py", line 1741, in handle_exception
    reraise(exc_type, exc_value, tb)
  File "/home/ubuntu/.local/lib/python2.7/site-packages/flask/app.py", line 2292, in wsgi_app
    response = self.full_dispatch_request()
  File "/home/ubuntu/.local/lib/python2.7/site-packages/flask/app.py", line 1815, in full_dispatch_request
    rv = self.handle_user_exception(e)
  File "/home/ubuntu/.local/lib/python2.7/site-packages/flask/app.py", line 1718, in handle_user_exception
    reraise(exc_type, exc_value, tb)
  File "/home/ubuntu/.local/lib/python2.7/site-packages/flask/app.py", line 1813, in full_dispatch_request
    rv = self.dispatch_request()
  File "/home/ubuntu/.local/lib/python2.7/site-packages/flask/app.py", line 1799, in dispatch_request
    return self.view_functions[rule.endpoint](**req.view_args)
  File "/home/ubuntu/.local/lib/python2.7/site-packages/dash/dash.py", line 558, in dispatch
    return self.callback_map[target_id]['callback'](*args)
  File "/home/ubuntu/.local/lib/python2.7/site-packages/dash/dash.py", line 515, in add_context
    output_value = func(*args, **kwargs)
  File "/home/ubuntu/twitch-emotes/src/dash/live.py", line 104, in update_graph_scatter
    max_y = max([max(Y),max(Z)])
ValueError: max() arg is an empty sequence
173.230.66.78 - - [09/Jul/2018 03:20:04] "POST /_dash-update-component HTTP/1.1" 200 -
173.230.66.78 - - [09/Jul/2018 03:20:08] "POST /_dash-update-component HTTP/1.1" 500 -
Traceback (most recent call last):
  File "/home/ubuntu/.local/lib/python2.7/site-packages/flask/app.py", line 2309, in __call__
    return self.wsgi_app(environ, start_response)
  File "/home/ubuntu/.local/lib/python2.7/site-packages/flask/app.py", line 2295, in wsgi_app
    response = self.handle_exception(e)
  File "/home/ubuntu/.local/lib/python2.7/site-packages/flask/app.py", line 1741, in handle_exception
    reraise(exc_type, exc_value, tb)
  File "/home/ubuntu/.local/lib/python2.7/site-packages/flask/app.py", line 2292, in wsgi_app
    response = self.full_dispatch_request()
  File "/home/ubuntu/.local/lib/python2.7/site-packages/flask/app.py", line 1815, in full_dispatch_request
    rv = self.handle_user_exception(e)
  File "/home/ubuntu/.local/lib/python2.7/site-packages/flask/app.py", line 1718, in handle_user_exception
    reraise(exc_type, exc_value, tb)
  File "/home/ubuntu/.local/lib/python2.7/site-packages/flask/app.py", line 1813, in full_dispatch_request
    rv = self.dispatch_request()
  File "/home/ubuntu/.local/lib/python2.7/site-packages/flask/app.py", line 1799, in dispatch_request
    return self.view_functions[rule.endpoint](**req.view_args)
  File "/home/ubuntu/.local/lib/python2.7/site-packages/dash/dash.py", line 558, in dispatch
    return self.callback_map[target_id]['callback'](*args)
  File "/home/ubuntu/.local/lib/python2.7/site-packages/dash/dash.py", line 515, in add_context
    output_value = func(*args, **kwargs)
  File "/home/ubuntu/twitch-emotes/src/dash/live.py", line 104, in update_graph_scatter
    max_y = max([max(Y),max(Z)])
ValueError: max() arg is an empty sequence
173.230.66.78 - - [09/Jul/2018 03:20:09] "POST /_dash-update-component HTTP/1.1" 200 -
173.230.66.78 - - [09/Jul/2018 03:20:13] "POST /_dash-update-component HTTP/1.1" 500 -
Traceback (most recent call last):
  File "/home/ubuntu/.local/lib/python2.7/site-packages/flask/app.py", line 2309, in __call__
    return self.wsgi_app(environ, start_response)
  File "/home/ubuntu/.local/lib/python2.7/site-packages/flask/app.py", line 2295, in wsgi_app
    response = self.handle_exception(e)
  File "/home/ubuntu/.local/lib/python2.7/site-packages/flask/app.py", line 1741, in handle_exception
    reraise(exc_type, exc_value, tb)
  File "/home/ubuntu/.local/lib/python2.7/site-packages/flask/app.py", line 2292, in wsgi_app
    response = self.full_dispatch_request()
  File "/home/ubuntu/.local/lib/python2.7/site-packages/flask/app.py", line 1815, in full_dispatch_request
    rv = self.handle_user_exception(e)
  File "/home/ubuntu/.local/lib/python2.7/site-packages/flask/app.py", line 1718, in handle_user_exception
    reraise(exc_type, exc_value, tb)
  File "/home/ubuntu/.local/lib/python2.7/site-packages/flask/app.py", line 1813, in full_dispatch_request
    rv = self.dispatch_request()
  File "/home/ubuntu/.local/lib/python2.7/site-packages/flask/app.py", line 1799, in dispatch_request
    return self.view_functions[rule.endpoint](**req.view_args)
  File "/home/ubuntu/.local/lib/python2.7/site-packages/dash/dash.py", line 558, in dispatch
    return self.callback_map[target_id]['callback'](*args)
  File "/home/ubuntu/.local/lib/python2.7/site-packages/dash/dash.py", line 515, in add_context
    output_value = func(*args, **kwargs)
  File "/home/ubuntu/twitch-emotes/src/dash/live.py", line 104, in update_graph_scatter
    max_y = max([max(Y),max(Z)])
ValueError: max() arg is an empty sequence
173.230.66.78 - - [09/Jul/2018 03:20:14] "POST /_dash-update-component HTTP/1.1" 200 -
173.230.66.78 - - [09/Jul/2018 03:20:18] "POST /_dash-update-component HTTP/1.1" 500 -
Traceback (most recent call last):
  File "/home/ubuntu/.local/lib/python2.7/site-packages/flask/app.py", line 2309, in __call__
    return self.wsgi_app(environ, start_response)
  File "/home/ubuntu/.local/lib/python2.7/site-packages/flask/app.py", line 2295, in wsgi_app
    response = self.handle_exception(e)
  File "/home/ubuntu/.local/lib/python2.7/site-packages/flask/app.py", line 1741, in handle_exception
    reraise(exc_type, exc_value, tb)
  File "/home/ubuntu/.local/lib/python2.7/site-packages/flask/app.py", line 2292, in wsgi_app
    response = self.full_dispatch_request()
  File "/home/ubuntu/.local/lib/python2.7/site-packages/flask/app.py", line 1815, in full_dispatch_request
    rv = self.handle_user_exception(e)
  File "/home/ubuntu/.local/lib/python2.7/site-packages/flask/app.py", line 1718, in handle_user_exception
    reraise(exc_type, exc_value, tb)
  File "/home/ubuntu/.local/lib/python2.7/site-packages/flask/app.py", line 1813, in full_dispatch_request
    rv = self.dispatch_request()
  File "/home/ubuntu/.local/lib/python2.7/site-packages/flask/app.py", line 1799, in dispatch_request
    return self.view_functions[rule.endpoint](**req.view_args)
  File "/home/ubuntu/.local/lib/python2.7/site-packages/dash/dash.py", line 558, in dispatch
    return self.callback_map[target_id]['callback'](*args)
  File "/home/ubuntu/.local/lib/python2.7/site-packages/dash/dash.py", line 515, in add_context
    output_value = func(*args, **kwargs)
  File "/home/ubuntu/twitch-emotes/src/dash/live.py", line 104, in update_graph_scatter
    max_y = max([max(Y),max(Z)])
ValueError: max() arg is an empty sequence
173.230.66.78 - - [09/Jul/2018 03:20:19] "POST /_dash-update-component HTTP/1.1" 200 -
 * Detected change in '/home/ubuntu/twitch-emotes/src/dash/live.py', reloading
call this func
 * Restarting with stat
 * Debugger is active!
 * Debugger PIN: 187-529-304
173.230.66.78 - - [09/Jul/2018 03:20:25] "POST /_dash-update-component HTTP/1.1" 200 -
173.230.66.78 - - [09/Jul/2018 03:20:28] "POST /_dash-update-component HTTP/1.1" 500 -
Traceback (most recent call last):
  File "/home/ubuntu/.local/lib/python2.7/site-packages/flask/app.py", line 2309, in __call__
    return self.wsgi_app(environ, start_response)
  File "/home/ubuntu/.local/lib/python2.7/site-packages/flask/app.py", line 2295, in wsgi_app
    response = self.handle_exception(e)
  File "/home/ubuntu/.local/lib/python2.7/site-packages/flask/app.py", line 1741, in handle_exception
    reraise(exc_type, exc_value, tb)
  File "/home/ubuntu/.local/lib/python2.7/site-packages/flask/app.py", line 2292, in wsgi_app
    response = self.full_dispatch_request()
  File "/home/ubuntu/.local/lib/python2.7/site-packages/flask/app.py", line 1815, in full_dispatch_request
    rv = self.handle_user_exception(e)
  File "/home/ubuntu/.local/lib/python2.7/site-packages/flask/app.py", line 1718, in handle_user_exception
    reraise(exc_type, exc_value, tb)
  File "/home/ubuntu/.local/lib/python2.7/site-packages/flask/app.py", line 1813, in full_dispatch_request
    rv = self.dispatch_request()
  File "/home/ubuntu/.local/lib/python2.7/site-packages/flask/app.py", line 1799, in dispatch_request
    return self.view_functions[rule.endpoint](**req.view_args)
  File "/home/ubuntu/.local/lib/python2.7/site-packages/dash/dash.py", line 558, in dispatch
    return self.callback_map[target_id]['callback'](*args)
  File "/home/ubuntu/.local/lib/python2.7/site-packages/dash/dash.py", line 515, in add_context
    output_value = func(*args, **kwargs)
  File "/home/ubuntu/twitch-emotes/src/dash/live.py", line 105, in update_graph_scatter
    max_y = max([max(Y),max(Z)])
ValueError: max() arg is an empty sequence
173.230.66.78 - - [09/Jul/2018 03:20:29] "POST /_dash-update-component HTTP/1.1" 200 -
173.230.66.78 - - [09/Jul/2018 03:20:33] "POST /_dash-update-component HTTP/1.1" 500 -
Traceback (most recent call last):
  File "/home/ubuntu/.local/lib/python2.7/site-packages/flask/app.py", line 2309, in __call__
    return self.wsgi_app(environ, start_response)
  File "/home/ubuntu/.local/lib/python2.7/site-packages/flask/app.py", line 2295, in wsgi_app
    response = self.handle_exception(e)
  File "/home/ubuntu/.local/lib/python2.7/site-packages/flask/app.py", line 1741, in handle_exception
    reraise(exc_type, exc_value, tb)
  File "/home/ubuntu/.local/lib/python2.7/site-packages/flask/app.py", line 2292, in wsgi_app
    response = self.full_dispatch_request()
  File "/home/ubuntu/.local/lib/python2.7/site-packages/flask/app.py", line 1815, in full_dispatch_request
    rv = self.handle_user_exception(e)
  File "/home/ubuntu/.local/lib/python2.7/site-packages/flask/app.py", line 1718, in handle_user_exception
    reraise(exc_type, exc_value, tb)
  File "/home/ubuntu/.local/lib/python2.7/site-packages/flask/app.py", line 1813, in full_dispatch_request
    rv = self.dispatch_request()
  File "/home/ubuntu/.local/lib/python2.7/site-packages/flask/app.py", line 1799, in dispatch_request
    return self.view_functions[rule.endpoint](**req.view_args)
  File "/home/ubuntu/.local/lib/python2.7/site-packages/dash/dash.py", line 558, in dispatch
    return self.callback_map[target_id]['callback'](*args)
  File "/home/ubuntu/.local/lib/python2.7/site-packages/dash/dash.py", line 515, in add_context
    output_value = func(*args, **kwargs)
  File "/home/ubuntu/twitch-emotes/src/dash/live.py", line 105, in update_graph_scatter
    max_y = max([max(Y),max(Z)])
ValueError: max() arg is an empty sequence
173.230.66.78 - - [09/Jul/2018 03:20:34] "POST /_dash-update-component HTTP/1.1" 200 -
173.230.66.78 - - [09/Jul/2018 03:20:38] "POST /_dash-update-component HTTP/1.1" 500 -
Traceback (most recent call last):
  File "/home/ubuntu/.local/lib/python2.7/site-packages/flask/app.py", line 2309, in __call__
    return self.wsgi_app(environ, start_response)
  File "/home/ubuntu/.local/lib/python2.7/site-packages/flask/app.py", line 2295, in wsgi_app
    response = self.handle_exception(e)
  File "/home/ubuntu/.local/lib/python2.7/site-packages/flask/app.py", line 1741, in handle_exception
    reraise(exc_type, exc_value, tb)
  File "/home/ubuntu/.local/lib/python2.7/site-packages/flask/app.py", line 2292, in wsgi_app
    response = self.full_dispatch_request()
  File "/home/ubuntu/.local/lib/python2.7/site-packages/flask/app.py", line 1815, in full_dispatch_request
    rv = self.handle_user_exception(e)
  File "/home/ubuntu/.local/lib/python2.7/site-packages/flask/app.py", line 1718, in handle_user_exception
    reraise(exc_type, exc_value, tb)
  File "/home/ubuntu/.local/lib/python2.7/site-packages/flask/app.py", line 1813, in full_dispatch_request
    rv = self.dispatch_request()
  File "/home/ubuntu/.local/lib/python2.7/site-packages/flask/app.py", line 1799, in dispatch_request
    return self.view_functions[rule.endpoint](**req.view_args)
  File "/home/ubuntu/.local/lib/python2.7/site-packages/dash/dash.py", line 558, in dispatch
    return self.callback_map[target_id]['callback'](*args)
  File "/home/ubuntu/.local/lib/python2.7/site-packages/dash/dash.py", line 515, in add_context
    output_value = func(*args, **kwargs)
  File "/home/ubuntu/twitch-emotes/src/dash/live.py", line 105, in update_graph_scatter
    max_y = max([max(Y),max(Z)])
ValueError: max() arg is an empty sequence
173.230.66.78 - - [09/Jul/2018 03:20:39] "POST /_dash-update-component HTTP/1.1" 200 -
173.230.66.78 - - [09/Jul/2018 03:20:43] "POST /_dash-update-component HTTP/1.1" 500 -
Traceback (most recent call last):
  File "/home/ubuntu/.local/lib/python2.7/site-packages/flask/app.py", line 2309, in __call__
    return self.wsgi_app(environ, start_response)
  File "/home/ubuntu/.local/lib/python2.7/site-packages/flask/app.py", line 2295, in wsgi_app
    response = self.handle_exception(e)
  File "/home/ubuntu/.local/lib/python2.7/site-packages/flask/app.py", line 1741, in handle_exception
    reraise(exc_type, exc_value, tb)
  File "/home/ubuntu/.local/lib/python2.7/site-packages/flask/app.py", line 2292, in wsgi_app
    response = self.full_dispatch_request()
  File "/home/ubuntu/.local/lib/python2.7/site-packages/flask/app.py", line 1815, in full_dispatch_request
    rv = self.handle_user_exception(e)
  File "/home/ubuntu/.local/lib/python2.7/site-packages/flask/app.py", line 1718, in handle_user_exception
    reraise(exc_type, exc_value, tb)
  File "/home/ubuntu/.local/lib/python2.7/site-packages/flask/app.py", line 1813, in full_dispatch_request
    rv = self.dispatch_request()
  File "/home/ubuntu/.local/lib/python2.7/site-packages/flask/app.py", line 1799, in dispatch_request
    return self.view_functions[rule.endpoint](**req.view_args)
  File "/home/ubuntu/.local/lib/python2.7/site-packages/dash/dash.py", line 558, in dispatch
    return self.callback_map[target_id]['callback'](*args)
  File "/home/ubuntu/.local/lib/python2.7/site-packages/dash/dash.py", line 515, in add_context
    output_value = func(*args, **kwargs)
  File "/home/ubuntu/twitch-emotes/src/dash/live.py", line 105, in update_graph_scatter
    max_y = max([max(Y),max(Z)])
ValueError: max() arg is an empty sequence
173.230.66.78 - - [09/Jul/2018 03:20:44] "POST /_dash-update-component HTTP/1.1" 200 -
173.230.66.78 - - [09/Jul/2018 03:20:48] "POST /_dash-update-component HTTP/1.1" 500 -
Traceback (most recent call last):
  File "/home/ubuntu/.local/lib/python2.7/site-packages/flask/app.py", line 2309, in __call__
    return self.wsgi_app(environ, start_response)
  File "/home/ubuntu/.local/lib/python2.7/site-packages/flask/app.py", line 2295, in wsgi_app
    response = self.handle_exception(e)
  File "/home/ubuntu/.local/lib/python2.7/site-packages/flask/app.py", line 1741, in handle_exception
    reraise(exc_type, exc_value, tb)
  File "/home/ubuntu/.local/lib/python2.7/site-packages/flask/app.py", line 2292, in wsgi_app
    response = self.full_dispatch_request()
  File "/home/ubuntu/.local/lib/python2.7/site-packages/flask/app.py", line 1815, in full_dispatch_request
    rv = self.handle_user_exception(e)
  File "/home/ubuntu/.local/lib/python2.7/site-packages/flask/app.py", line 1718, in handle_user_exception
    reraise(exc_type, exc_value, tb)
  File "/home/ubuntu/.local/lib/python2.7/site-packages/flask/app.py", line 1813, in full_dispatch_request
    rv = self.dispatch_request()
  File "/home/ubuntu/.local/lib/python2.7/site-packages/flask/app.py", line 1799, in dispatch_request
    return self.view_functions[rule.endpoint](**req.view_args)
  File "/home/ubuntu/.local/lib/python2.7/site-packages/dash/dash.py", line 558, in dispatch
    return self.callback_map[target_id]['callback'](*args)
  File "/home/ubuntu/.local/lib/python2.7/site-packages/dash/dash.py", line 515, in add_context
    output_value = func(*args, **kwargs)
  File "/home/ubuntu/twitch-emotes/src/dash/live.py", line 105, in update_graph_scatter
    max_y = max([max(Y),max(Z)])
ValueError: max() arg is an empty sequence
173.230.66.78 - - [09/Jul/2018 03:20:49] "POST /_dash-update-component HTTP/1.1" 200 -
173.230.66.78 - - [09/Jul/2018 03:20:53] "POST /_dash-update-component HTTP/1.1" 500 -
Traceback (most recent call last):
  File "/home/ubuntu/.local/lib/python2.7/site-packages/flask/app.py", line 2309, in __call__
    return self.wsgi_app(environ, start_response)
  File "/home/ubuntu/.local/lib/python2.7/site-packages/flask/app.py", line 2295, in wsgi_app
    response = self.handle_exception(e)
  File "/home/ubuntu/.local/lib/python2.7/site-packages/flask/app.py", line 1741, in handle_exception
    reraise(exc_type, exc_value, tb)
  File "/home/ubuntu/.local/lib/python2.7/site-packages/flask/app.py", line 2292, in wsgi_app
    response = self.full_dispatch_request()
  File "/home/ubuntu/.local/lib/python2.7/site-packages/flask/app.py", line 1815, in full_dispatch_request
    rv = self.handle_user_exception(e)
  File "/home/ubuntu/.local/lib/python2.7/site-packages/flask/app.py", line 1718, in handle_user_exception
    reraise(exc_type, exc_value, tb)
  File "/home/ubuntu/.local/lib/python2.7/site-packages/flask/app.py", line 1813, in full_dispatch_request
    rv = self.dispatch_request()
  File "/home/ubuntu/.local/lib/python2.7/site-packages/flask/app.py", line 1799, in dispatch_request
    return self.view_functions[rule.endpoint](**req.view_args)
  File "/home/ubuntu/.local/lib/python2.7/site-packages/dash/dash.py", line 558, in dispatch
    return self.callback_map[target_id]['callback'](*args)
  File "/home/ubuntu/.local/lib/python2.7/site-packages/dash/dash.py", line 515, in add_context
    output_value = func(*args, **kwargs)
  File "/home/ubuntu/twitch-emotes/src/dash/live.py", line 105, in update_graph_scatter
    max_y = max([max(Y),max(Z)])
ValueError: max() arg is an empty sequence
173.230.66.78 - - [09/Jul/2018 03:20:54] "POST /_dash-update-component HTTP/1.1" 200 -
173.230.66.78 - - [09/Jul/2018 03:20:58] "POST /_dash-update-component HTTP/1.1" 500 -
Traceback (most recent call last):
  File "/home/ubuntu/.local/lib/python2.7/site-packages/flask/app.py", line 2309, in __call__
    return self.wsgi_app(environ, start_response)
  File "/home/ubuntu/.local/lib/python2.7/site-packages/flask/app.py", line 2295, in wsgi_app
    response = self.handle_exception(e)
  File "/home/ubuntu/.local/lib/python2.7/site-packages/flask/app.py", line 1741, in handle_exception
    reraise(exc_type, exc_value, tb)
  File "/home/ubuntu/.local/lib/python2.7/site-packages/flask/app.py", line 2292, in wsgi_app
    response = self.full_dispatch_request()
  File "/home/ubuntu/.local/lib/python2.7/site-packages/flask/app.py", line 1815, in full_dispatch_request
    rv = self.handle_user_exception(e)
  File "/home/ubuntu/.local/lib/python2.7/site-packages/flask/app.py", line 1718, in handle_user_exception
    reraise(exc_type, exc_value, tb)
  File "/home/ubuntu/.local/lib/python2.7/site-packages/flask/app.py", line 1813, in full_dispatch_request
    rv = self.dispatch_request()
  File "/home/ubuntu/.local/lib/python2.7/site-packages/flask/app.py", line 1799, in dispatch_request
    return self.view_functions[rule.endpoint](**req.view_args)
  File "/home/ubuntu/.local/lib/python2.7/site-packages/dash/dash.py", line 558, in dispatch
    return self.callback_map[target_id]['callback'](*args)
  File "/home/ubuntu/.local/lib/python2.7/site-packages/dash/dash.py", line 515, in add_context
    output_value = func(*args, **kwargs)
  File "/home/ubuntu/twitch-emotes/src/dash/live.py", line 105, in update_graph_scatter
    max_y = max([max(Y),max(Z)])
ValueError: max() arg is an empty sequence
173.230.66.78 - - [09/Jul/2018 03:20:59] "POST /_dash-update-component HTTP/1.1" 200 -
173.230.66.78 - - [09/Jul/2018 03:21:03] "POST /_dash-update-component HTTP/1.1" 500 -
Traceback (most recent call last):
  File "/home/ubuntu/.local/lib/python2.7/site-packages/flask/app.py", line 2309, in __call__
    return self.wsgi_app(environ, start_response)
  File "/home/ubuntu/.local/lib/python2.7/site-packages/flask/app.py", line 2295, in wsgi_app
    response = self.handle_exception(e)
  File "/home/ubuntu/.local/lib/python2.7/site-packages/flask/app.py", line 1741, in handle_exception
    reraise(exc_type, exc_value, tb)
  File "/home/ubuntu/.local/lib/python2.7/site-packages/flask/app.py", line 2292, in wsgi_app
    response = self.full_dispatch_request()
  File "/home/ubuntu/.local/lib/python2.7/site-packages/flask/app.py", line 1815, in full_dispatch_request
    rv = self.handle_user_exception(e)
  File "/home/ubuntu/.local/lib/python2.7/site-packages/flask/app.py", line 1718, in handle_user_exception
    reraise(exc_type, exc_value, tb)
  File "/home/ubuntu/.local/lib/python2.7/site-packages/flask/app.py", line 1813, in full_dispatch_request
    rv = self.dispatch_request()
  File "/home/ubuntu/.local/lib/python2.7/site-packages/flask/app.py", line 1799, in dispatch_request
    return self.view_functions[rule.endpoint](**req.view_args)
  File "/home/ubuntu/.local/lib/python2.7/site-packages/dash/dash.py", line 558, in dispatch
    return self.callback_map[target_id]['callback'](*args)
  File "/home/ubuntu/.local/lib/python2.7/site-packages/dash/dash.py", line 515, in add_context
    output_value = func(*args, **kwargs)
  File "/home/ubuntu/twitch-emotes/src/dash/live.py", line 105, in update_graph_scatter
    max_y = max([max(Y),max(Z)])
ValueError: max() arg is an empty sequence
173.230.66.78 - - [09/Jul/2018 03:21:04] "POST /_dash-update-component HTTP/1.1" 200 -
173.230.66.78 - - [09/Jul/2018 03:21:08] "POST /_dash-update-component HTTP/1.1" 500 -
Traceback (most recent call last):
  File "/home/ubuntu/.local/lib/python2.7/site-packages/flask/app.py", line 2309, in __call__
    return self.wsgi_app(environ, start_response)
  File "/home/ubuntu/.local/lib/python2.7/site-packages/flask/app.py", line 2295, in wsgi_app
    response = self.handle_exception(e)
  File "/home/ubuntu/.local/lib/python2.7/site-packages/flask/app.py", line 1741, in handle_exception
    reraise(exc_type, exc_value, tb)
  File "/home/ubuntu/.local/lib/python2.7/site-packages/flask/app.py", line 2292, in wsgi_app
    response = self.full_dispatch_request()
  File "/home/ubuntu/.local/lib/python2.7/site-packages/flask/app.py", line 1815, in full_dispatch_request
    rv = self.handle_user_exception(e)
  File "/home/ubuntu/.local/lib/python2.7/site-packages/flask/app.py", line 1718, in handle_user_exception
    reraise(exc_type, exc_value, tb)
  File "/home/ubuntu/.local/lib/python2.7/site-packages/flask/app.py", line 1813, in full_dispatch_request
    rv = self.dispatch_request()
  File "/home/ubuntu/.local/lib/python2.7/site-packages/flask/app.py", line 1799, in dispatch_request
    return self.view_functions[rule.endpoint](**req.view_args)
  File "/home/ubuntu/.local/lib/python2.7/site-packages/dash/dash.py", line 558, in dispatch
    return self.callback_map[target_id]['callback'](*args)
  File "/home/ubuntu/.local/lib/python2.7/site-packages/dash/dash.py", line 515, in add_context
    output_value = func(*args, **kwargs)
  File "/home/ubuntu/twitch-emotes/src/dash/live.py", line 105, in update_graph_scatter
    max_y = max([max(Y),max(Z)])
ValueError: max() arg is an empty sequence
173.230.66.78 - - [09/Jul/2018 03:21:09] "POST /_dash-update-component HTTP/1.1" 200 -
173.230.66.78 - - [09/Jul/2018 03:21:13] "POST /_dash-update-component HTTP/1.1" 500 -
Traceback (most recent call last):
  File "/home/ubuntu/.local/lib/python2.7/site-packages/flask/app.py", line 2309, in __call__
    return self.wsgi_app(environ, start_response)
  File "/home/ubuntu/.local/lib/python2.7/site-packages/flask/app.py", line 2295, in wsgi_app
    response = self.handle_exception(e)
  File "/home/ubuntu/.local/lib/python2.7/site-packages/flask/app.py", line 1741, in handle_exception
    reraise(exc_type, exc_value, tb)
  File "/home/ubuntu/.local/lib/python2.7/site-packages/flask/app.py", line 2292, in wsgi_app
    response = self.full_dispatch_request()
  File "/home/ubuntu/.local/lib/python2.7/site-packages/flask/app.py", line 1815, in full_dispatch_request
    rv = self.handle_user_exception(e)
  File "/home/ubuntu/.local/lib/python2.7/site-packages/flask/app.py", line 1718, in handle_user_exception
    reraise(exc_type, exc_value, tb)
  File "/home/ubuntu/.local/lib/python2.7/site-packages/flask/app.py", line 1813, in full_dispatch_request
    rv = self.dispatch_request()
  File "/home/ubuntu/.local/lib/python2.7/site-packages/flask/app.py", line 1799, in dispatch_request
    return self.view_functions[rule.endpoint](**req.view_args)
  File "/home/ubuntu/.local/lib/python2.7/site-packages/dash/dash.py", line 558, in dispatch
    return self.callback_map[target_id]['callback'](*args)
  File "/home/ubuntu/.local/lib/python2.7/site-packages/dash/dash.py", line 515, in add_context
    output_value = func(*args, **kwargs)
  File "/home/ubuntu/twitch-emotes/src/dash/live.py", line 105, in update_graph_scatter
    max_y = max([max(Y),max(Z)])
ValueError: max() arg is an empty sequence
173.230.66.78 - - [09/Jul/2018 03:21:15] "POST /_dash-update-component HTTP/1.1" 200 -
173.230.66.78 - - [09/Jul/2018 03:21:18] "POST /_dash-update-component HTTP/1.1" 500 -
Traceback (most recent call last):
  File "/home/ubuntu/.local/lib/python2.7/site-packages/flask/app.py", line 2309, in __call__
    return self.wsgi_app(environ, start_response)
  File "/home/ubuntu/.local/lib/python2.7/site-packages/flask/app.py", line 2295, in wsgi_app
    response = self.handle_exception(e)
  File "/home/ubuntu/.local/lib/python2.7/site-packages/flask/app.py", line 1741, in handle_exception
    reraise(exc_type, exc_value, tb)
  File "/home/ubuntu/.local/lib/python2.7/site-packages/flask/app.py", line 2292, in wsgi_app
    response = self.full_dispatch_request()
  File "/home/ubuntu/.local/lib/python2.7/site-packages/flask/app.py", line 1815, in full_dispatch_request
    rv = self.handle_user_exception(e)
  File "/home/ubuntu/.local/lib/python2.7/site-packages/flask/app.py", line 1718, in handle_user_exception
    reraise(exc_type, exc_value, tb)
  File "/home/ubuntu/.local/lib/python2.7/site-packages/flask/app.py", line 1813, in full_dispatch_request
    rv = self.dispatch_request()
  File "/home/ubuntu/.local/lib/python2.7/site-packages/flask/app.py", line 1799, in dispatch_request
    return self.view_functions[rule.endpoint](**req.view_args)
  File "/home/ubuntu/.local/lib/python2.7/site-packages/dash/dash.py", line 558, in dispatch
    return self.callback_map[target_id]['callback'](*args)
  File "/home/ubuntu/.local/lib/python2.7/site-packages/dash/dash.py", line 515, in add_context
    output_value = func(*args, **kwargs)
  File "/home/ubuntu/twitch-emotes/src/dash/live.py", line 105, in update_graph_scatter
    max_y = max([max(Y),max(Z)])
ValueError: max() arg is an empty sequence
173.230.66.78 - - [09/Jul/2018 03:21:19] "POST /_dash-update-component HTTP/1.1" 200 -
173.230.66.78 - - [09/Jul/2018 03:21:23] "POST /_dash-update-component HTTP/1.1" 500 -
Traceback (most recent call last):
  File "/home/ubuntu/.local/lib/python2.7/site-packages/flask/app.py", line 2309, in __call__
    return self.wsgi_app(environ, start_response)
  File "/home/ubuntu/.local/lib/python2.7/site-packages/flask/app.py", line 2295, in wsgi_app
    response = self.handle_exception(e)
  File "/home/ubuntu/.local/lib/python2.7/site-packages/flask/app.py", line 1741, in handle_exception
    reraise(exc_type, exc_value, tb)
  File "/home/ubuntu/.local/lib/python2.7/site-packages/flask/app.py", line 2292, in wsgi_app
    response = self.full_dispatch_request()
  File "/home/ubuntu/.local/lib/python2.7/site-packages/flask/app.py", line 1815, in full_dispatch_request
    rv = self.handle_user_exception(e)
  File "/home/ubuntu/.local/lib/python2.7/site-packages/flask/app.py", line 1718, in handle_user_exception
    reraise(exc_type, exc_value, tb)
  File "/home/ubuntu/.local/lib/python2.7/site-packages/flask/app.py", line 1813, in full_dispatch_request
    rv = self.dispatch_request()
  File "/home/ubuntu/.local/lib/python2.7/site-packages/flask/app.py", line 1799, in dispatch_request
    return self.view_functions[rule.endpoint](**req.view_args)
  File "/home/ubuntu/.local/lib/python2.7/site-packages/dash/dash.py", line 558, in dispatch
    return self.callback_map[target_id]['callback'](*args)
  File "/home/ubuntu/.local/lib/python2.7/site-packages/dash/dash.py", line 515, in add_context
    output_value = func(*args, **kwargs)
  File "/home/ubuntu/twitch-emotes/src/dash/live.py", line 105, in update_graph_scatter
    max_y = max([max(Y),max(Z)])
ValueError: max() arg is an empty sequence
173.230.66.78 - - [09/Jul/2018 03:21:24] "POST /_dash-update-component HTTP/1.1" 200 -
173.230.66.78 - - [09/Jul/2018 03:21:28] "POST /_dash-update-component HTTP/1.1" 500 -
Traceback (most recent call last):
  File "/home/ubuntu/.local/lib/python2.7/site-packages/flask/app.py", line 2309, in __call__
    return self.wsgi_app(environ, start_response)
  File "/home/ubuntu/.local/lib/python2.7/site-packages/flask/app.py", line 2295, in wsgi_app
    response = self.handle_exception(e)
  File "/home/ubuntu/.local/lib/python2.7/site-packages/flask/app.py", line 1741, in handle_exception
    reraise(exc_type, exc_value, tb)
  File "/home/ubuntu/.local/lib/python2.7/site-packages/flask/app.py", line 2292, in wsgi_app
    response = self.full_dispatch_request()
  File "/home/ubuntu/.local/lib/python2.7/site-packages/flask/app.py", line 1815, in full_dispatch_request
    rv = self.handle_user_exception(e)
  File "/home/ubuntu/.local/lib/python2.7/site-packages/flask/app.py", line 1718, in handle_user_exception
    reraise(exc_type, exc_value, tb)
  File "/home/ubuntu/.local/lib/python2.7/site-packages/flask/app.py", line 1813, in full_dispatch_request
    rv = self.dispatch_request()
  File "/home/ubuntu/.local/lib/python2.7/site-packages/flask/app.py", line 1799, in dispatch_request
    return self.view_functions[rule.endpoint](**req.view_args)
  File "/home/ubuntu/.local/lib/python2.7/site-packages/dash/dash.py", line 558, in dispatch
    return self.callback_map[target_id]['callback'](*args)
  File "/home/ubuntu/.local/lib/python2.7/site-packages/dash/dash.py", line 515, in add_context
    output_value = func(*args, **kwargs)
  File "/home/ubuntu/twitch-emotes/src/dash/live.py", line 105, in update_graph_scatter
    max_y = max([max(Y),max(Z)])
ValueError: max() arg is an empty sequence
173.230.66.78 - - [09/Jul/2018 03:21:30] "POST /_dash-update-component HTTP/1.1" 200 -
173.230.66.78 - - [09/Jul/2018 03:21:33] "POST /_dash-update-component HTTP/1.1" 500 -
Traceback (most recent call last):
  File "/home/ubuntu/.local/lib/python2.7/site-packages/flask/app.py", line 2309, in __call__
    return self.wsgi_app(environ, start_response)
  File "/home/ubuntu/.local/lib/python2.7/site-packages/flask/app.py", line 2295, in wsgi_app
    response = self.handle_exception(e)
  File "/home/ubuntu/.local/lib/python2.7/site-packages/flask/app.py", line 1741, in handle_exception
    reraise(exc_type, exc_value, tb)
  File "/home/ubuntu/.local/lib/python2.7/site-packages/flask/app.py", line 2292, in wsgi_app
    response = self.full_dispatch_request()
  File "/home/ubuntu/.local/lib/python2.7/site-packages/flask/app.py", line 1815, in full_dispatch_request
    rv = self.handle_user_exception(e)
  File "/home/ubuntu/.local/lib/python2.7/site-packages/flask/app.py", line 1718, in handle_user_exception
    reraise(exc_type, exc_value, tb)
  File "/home/ubuntu/.local/lib/python2.7/site-packages/flask/app.py", line 1813, in full_dispatch_request
    rv = self.dispatch_request()
  File "/home/ubuntu/.local/lib/python2.7/site-packages/flask/app.py", line 1799, in dispatch_request
    return self.view_functions[rule.endpoint](**req.view_args)
  File "/home/ubuntu/.local/lib/python2.7/site-packages/dash/dash.py", line 558, in dispatch
    return self.callback_map[target_id]['callback'](*args)
  File "/home/ubuntu/.local/lib/python2.7/site-packages/dash/dash.py", line 515, in add_context
    output_value = func(*args, **kwargs)
  File "/home/ubuntu/twitch-emotes/src/dash/live.py", line 105, in update_graph_scatter
    max_y = max([max(Y),max(Z)])
ValueError: max() arg is an empty sequence
173.230.66.78 - - [09/Jul/2018 03:21:34] "POST /_dash-update-component HTTP/1.1" 200 -
173.230.66.78 - - [09/Jul/2018 03:21:38] "POST /_dash-update-component HTTP/1.1" 500 -
Traceback (most recent call last):
  File "/home/ubuntu/.local/lib/python2.7/site-packages/flask/app.py", line 2309, in __call__
    return self.wsgi_app(environ, start_response)
  File "/home/ubuntu/.local/lib/python2.7/site-packages/flask/app.py", line 2295, in wsgi_app
    response = self.handle_exception(e)
  File "/home/ubuntu/.local/lib/python2.7/site-packages/flask/app.py", line 1741, in handle_exception
    reraise(exc_type, exc_value, tb)
  File "/home/ubuntu/.local/lib/python2.7/site-packages/flask/app.py", line 2292, in wsgi_app
    response = self.full_dispatch_request()
  File "/home/ubuntu/.local/lib/python2.7/site-packages/flask/app.py", line 1815, in full_dispatch_request
    rv = self.handle_user_exception(e)
  File "/home/ubuntu/.local/lib/python2.7/site-packages/flask/app.py", line 1718, in handle_user_exception
    reraise(exc_type, exc_value, tb)
  File "/home/ubuntu/.local/lib/python2.7/site-packages/flask/app.py", line 1813, in full_dispatch_request
    rv = self.dispatch_request()
  File "/home/ubuntu/.local/lib/python2.7/site-packages/flask/app.py", line 1799, in dispatch_request
    return self.view_functions[rule.endpoint](**req.view_args)
  File "/home/ubuntu/.local/lib/python2.7/site-packages/dash/dash.py", line 558, in dispatch
    return self.callback_map[target_id]['callback'](*args)
  File "/home/ubuntu/.local/lib/python2.7/site-packages/dash/dash.py", line 515, in add_context
    output_value = func(*args, **kwargs)
  File "/home/ubuntu/twitch-emotes/src/dash/live.py", line 105, in update_graph_scatter
    max_y = max([max(Y),max(Z)])
ValueError: max() arg is an empty sequence
173.230.66.78 - - [09/Jul/2018 03:21:39] "POST /_dash-update-component HTTP/1.1" 200 -
173.230.66.78 - - [09/Jul/2018 03:21:43] "POST /_dash-update-component HTTP/1.1" 500 -
Traceback (most recent call last):
  File "/home/ubuntu/.local/lib/python2.7/site-packages/flask/app.py", line 2309, in __call__
    return self.wsgi_app(environ, start_response)
  File "/home/ubuntu/.local/lib/python2.7/site-packages/flask/app.py", line 2295, in wsgi_app
    response = self.handle_exception(e)
  File "/home/ubuntu/.local/lib/python2.7/site-packages/flask/app.py", line 1741, in handle_exception
    reraise(exc_type, exc_value, tb)
  File "/home/ubuntu/.local/lib/python2.7/site-packages/flask/app.py", line 2292, in wsgi_app
    response = self.full_dispatch_request()
  File "/home/ubuntu/.local/lib/python2.7/site-packages/flask/app.py", line 1815, in full_dispatch_request
    rv = self.handle_user_exception(e)
  File "/home/ubuntu/.local/lib/python2.7/site-packages/flask/app.py", line 1718, in handle_user_exception
    reraise(exc_type, exc_value, tb)
  File "/home/ubuntu/.local/lib/python2.7/site-packages/flask/app.py", line 1813, in full_dispatch_request
    rv = self.dispatch_request()
  File "/home/ubuntu/.local/lib/python2.7/site-packages/flask/app.py", line 1799, in dispatch_request
    return self.view_functions[rule.endpoint](**req.view_args)
  File "/home/ubuntu/.local/lib/python2.7/site-packages/dash/dash.py", line 558, in dispatch
    return self.callback_map[target_id]['callback'](*args)
  File "/home/ubuntu/.local/lib/python2.7/site-packages/dash/dash.py", line 515, in add_context
    output_value = func(*args, **kwargs)
  File "/home/ubuntu/twitch-emotes/src/dash/live.py", line 105, in update_graph_scatter
    max_y = max([max(Y),max(Z)])
ValueError: max() arg is an empty sequence
173.230.66.78 - - [09/Jul/2018 03:21:44] "POST /_dash-update-component HTTP/1.1" 200 -
